<?xml version="1.0" encoding="utf-8"?>
<!-- =================================================================================== -->
<!-- |    This document was autogenerated by xacro from dualarm_prbt.xacro             | -->
<!-- |    EDITING THIS FILE BY HAND IS NOT RECOMMENDED                                 | -->
<!-- =================================================================================== -->
<robot name="dualarm_prbt">
  <!-- schunk pg70 -->
  <!-- <xacro:include filename="$(find prbt_pg70_support)/urdf/pg70.urdf.xacro" /> -->
  <!-- gripper brackets -->
  <!-- <xacro:include filename="$(find prbt_support)/urdf/simple_gripper_brackets.urdf.xacro" /> -->
  <!-- Used for fixing robot to Gazebo -->
  <link name="table">
    <visual>
      <origin rpy="0 0 0" xyz="0 0 -0.03"/>
      <geometry>
        <box size="1.42 1.04 0.05"/>
      </geometry>
      <material name="grey">
        <color rgba="0.75 0.75 0.75 1"/>
      </material>
    </visual>
    <!-- Move space limitation -->
    <!-- left -->
    <!-- <collision>
      <origin rpy="0 0 0" xyz="-0.71 0 0.55"/>
      <geometry>
        <box size="0.01 1.04 1.1"/>
      </geometry>
    </collision> -->
    <!-- Right -->
    <!-- <collision>
      <origin rpy="0 0 0" xyz="0.71 0 0.55"/>
      <geometry>
        <box size="0.01 1.04 1.1"/>
      </geometry>
    </collision> -->
    <!-- Back -->
    <collision>
      <origin rpy="0 0 0" xyz="0 0.52 0.55"/>
      <geometry>
        <box size="1.42 0.01 1.1"/>
      </geometry>
    </collision>
    <!-- Front -->
    <!-- <collision>
      <origin rpy="0 0 0" xyz="0 -0.52 0.55"/>
      <geometry>
        <box size="1.42 0.01 1.1"/>
      </geometry>
    </collision> -->
    <!-- Bottom -->
    <collision>
      <origin rpy="0 0 0" xyz="0 0 -0.03"/>
      <geometry>
        <box size="1.42 1.04 0.05"/>
      </geometry>
    </collision>
  </link>
  <link name="box">
    <visual>
      <origin rpy="1.57 0 0" xyz="-0.95 0.635 -0.85"/>
      <geometry>
        <mesh filename="package://dualarm_exhibition/meshes/box.stl" scale="0.001 0.001 0.001"/>
      </geometry>
      <material name="yellow">
        <color rgba="1 1 0 1"/>
      </material>
    </visual>
    <collision>
      <origin rpy="1.57 0 0" xyz="-0.95 0.635 -0.85"/>
      <geometry>
        <mesh filename="package://dualarm_exhibition/meshes/box.stl" scale="0.001 0.001 0.001"/>
      </geometry>
    </collision>
  </link>
  <joint name="box_joint" type="fixed">
    <origin rpy="0 0 0" xyz="0 0 0"/>
    <parent link="table"/>
    <child link="box"/>
  </joint>
  <link name="flash_1">
    <visual>
      <origin rpy="1.57 0 0" xyz="-1 0.62 -0.85"/>
      <geometry>
        <mesh filename="package://dualarm_exhibition/meshes/flash_1.stl" scale="0.001 0.001 0.001"/>
      </geometry>
      <material name="yellow">
        <color rgba="1 1 0 1"/>
      </material>
    </visual>
    <collision>
      <origin rpy="1.57 0 0" xyz="-1 0.62 -0.85"/>
      <geometry>
        <mesh filename="package://dualarm_exhibition/meshes/flash_1.stl" scale="0.001 0.001 0.001"/>
      </geometry>
    </collision>
  </link>
  <joint name="flash_1_joint" type="fixed">
    <origin rpy="0 0 0" xyz="0 0 0"/>
    <parent link="table"/>
    <child link="flash_1"/>
  </joint>
  <link name="flash_2">
    <visual>
      <origin rpy="1.57 0 0" xyz="-0.999 0.62 -0.85"/>
      <geometry>
        <mesh filename="package://dualarm_exhibition/meshes/flash_2.stl" scale="0.001 0.001 0.001"/>
      </geometry>
      <material name="yellow">
        <color rgba="1 1 0 1"/>
      </material>
    </visual>
    <collision>
      <origin rpy="1.57 0 0" xyz="-0.999 0.62 -0.85"/>
      <geometry>
        <mesh filename="package://dualarm_exhibition/meshes/flash_2.stl" scale="0.001 0.001 0.001"/>
      </geometry>
    </collision>
  </link>
  <joint name="flash_2_joint" type="fixed">
    <origin rpy="0 0 0" xyz="0 0 0"/>
    <parent link="table"/>
    <child link="flash_2"/>
  </joint>
  <joint name="table_joint" type="fixed">
    <!-- <origin xyz="0 0 0" rpy="0 0 0" /> -->
    <parent link="table"/>
    <child link="stander"/>
  </joint>
  <link name="stander">
    <visual>
      <origin rpy="0 0 -1.57" xyz="0 0.233 0"/>
      <geometry>
        <mesh filename="package://dualarm_exhibition/meshes/torso.stl"/>
      </geometry>
      <material name="grey">
        <color rgba="0.6 0.6 0.6 1"/>
      </material>
    </visual>
    <collision>
      <origin rpy="0 0 -1.57" xyz="0 0.233 0"/>
      <geometry>
        <mesh filename="package://dualarm_exhibition/meshes/torso.stl"/>
      </geometry>
    </collision>
  </link>
  <!-- additional links for offset and rotation -->
  <joint name="left_fixture_joint" type="fixed">
    <origin rpy="0.14 -1.0472 2.33" xyz="0.068 0.213 0.3944"/>
    <parent link="stander"/>
    <child link="left_fixture"/>
  </joint>
  <link name="left_fixture"/>
  <joint name="right_fixture_joint" type="fixed">
    <origin rpy="-0.14 -1.0472 0.807" xyz="-0.068 0.213 0.3944"/>
    <parent link="stander"/>
    <child link="right_fixture"/>
  </joint>
  <link name="right_fixture"/>
  <!-- robot foot link -->
  <link name="left_arm_base_link">
    <inertial>
      <mass value="2.4"/>
      <inertia ixx="0" ixy="0" ixz="0" iyy="0" iyz="0" izz="0"/>
    </inertial>
    <visual>
      <origin rpy="0 0 0" xyz="0 0 0"/>
      <geometry>
        <mesh filename="package://prbt_support/meshes/foot.dae"/>
      </geometry>
    </visual>
    <collision>
      <origin rpy="3.14159265359 0 0" xyz="0 0 0.065"/>
      <geometry>
        <cylinder length="0.13" radius="0.09275"/>
      </geometry>
    </collision>
  </link>
  <!-- arm 1 joint -->
  <joint name="left_arm_joint_1" type="revolute">
    <origin rpy="0 0 -3.14159265359" xyz="0 0 0.2604"/>
    <parent link="left_arm_base_link"/>
    <child link="left_arm_link_1"/>
    <axis xyz="0 0 1"/>
    <limit effort="370" lower="-2.96706" upper="2.96706" velocity="1.57"/>
    <dynamics damping="15.0" friction="11"/>
  </joint>
  <!-- arm 1 link -->
  <link name="left_arm_link_1">
    <inertial>
      <mass value="7.1"/>
      <origin xyz="0 -0.026 -0.051"/>
      <inertia ixx="3.53e-2" ixy="0" ixz="0" iyy="3.01e-2" iyz="9.04e-3" izz="1.87e-2"/>
    </inertial>
    <visual>
      <origin rpy="0 0 0" xyz="0 0 0"/>
      <geometry>
        <mesh filename="package://prbt_support/meshes/link_1.dae"/>
      </geometry>
    </visual>
    <collision>
      <origin rpy="0 0 0" xyz="0 0 -0.08"/>
      <geometry>
        <cylinder length="0.10" radius="0.07"/>
      </geometry>
    </collision>
    <collision>
      <origin rpy="0 0 0" xyz="0 0 0"/>
      <geometry>
        <sphere radius="0.09"/>
      </geometry>
    </collision>
    <collision>
      <origin rpy="0 1.57079632679 1.57079632679" xyz="0 -0.10 0"/>
      <geometry>
        <cylinder length="0.10" radius="0.065"/>
      </geometry>
    </collision>
  </link>
  <!-- joint between arm_1_link and arm_2_link -->
  <joint name="left_arm_joint_2" type="revolute">
    <origin rpy="1.57079632679 0 0" xyz="0 0 0"/>
    <parent link="left_arm_link_1"/>
    <child link="left_arm_link_2"/>
    <axis xyz="0 0 1"/>
    <limit effort="370" lower="-2.53073" upper="2.53073" velocity="1.57"/>
    <dynamics damping="12.0" friction="10.0"/>
  </joint>
  <link name="left_arm_link_2">
    <inertial>
      <mass value="1.7"/>
      <origin xyz="0 0.162 0.134"/>
      <inertia ixx="3.58e-2" ixy="0" ixz="0" iyy="3.22e-3" iyz="-1.45e-3" izz="3.66e-2"/>
    </inertial>
    <visual name="first">
      <origin rpy="0 0 0" xyz="0 0 0"/>
      <geometry>
        <mesh filename="package://prbt_support/meshes/link_2.dae"/>
      </geometry>
    </visual>
    <collision>
      <origin rpy="0.174532925199 0 0" xyz="0 0.15 0.145"/>
      <geometry>
        <box size="0.121 0.27 0.065"/>
      </geometry>
    </collision>
    <collision>
      <origin rpy="-0.448798950513 0 0" xyz="0 0.3 0.145"/>
      <geometry>
        <box size="0.11 0.1 0.075"/>
      </geometry>
    </collision>
  </link>
  <!-- joint between arm_2_link and arm_3_link -->
  <joint name="left_arm_joint_3" type="revolute">
    <origin rpy="0 3.14159265359 0" xyz="0 0.35 0"/>
    <parent link="left_arm_link_2"/>
    <child link="left_arm_link_3"/>
    <axis xyz="0 0 1"/>
    <limit effort="176" lower="-2.35620" upper="2.35620" velocity="1.57"/>
    <dynamics damping="4.5" friction="4.5"/>
  </joint>
  <link name="left_arm_link_3">
    <inertial>
      <mass value="4.8"/>
      <origin xyz="0 0.043 -0.027"/>
      <inertia ixx="2.06e-2" ixy="0" ixz="0" iyy="1.08e-2" iyz="-5.36e-3" izz="1.63e-2"/>
    </inertial>
    <visual>
      <origin rpy="0 0 0" xyz="0 0 0"/>
      <geometry>
        <mesh filename="package://prbt_support/meshes/link_3.dae"/>
      </geometry>
    </visual>
    <collision>
      <origin rpy="0 0 0" xyz="0 0 -0.11"/>
      <geometry>
        <cylinder length="0.10" radius="0.06"/>
      </geometry>
    </collision>
    <collision>
      <origin rpy="0 0 0" xyz="0 0 0"/>
      <geometry>
        <sphere radius="0.085"/>
      </geometry>
    </collision>
    <collision>
      <origin rpy="0 1.57079632679 1.57079632679" xyz="0 0.10 0"/>
      <geometry>
        <cylinder length="0.10" radius="0.065"/>
      </geometry>
    </collision>
  </link>
  <!-- joint between arm_3_link and arm_4_link -->
  <joint name="left_arm_joint_4" type="revolute">
    <origin rpy="-1.57079632679 3.14159265359 0" xyz="0 0 0"/>
    <parent link="left_arm_link_3"/>
    <child link="left_arm_link_4"/>
    <axis xyz="0 0 1"/>
    <limit effort="176" lower="-2.96706" upper="2.96706" velocity="1.57"/>
    <dynamics damping="4.2" friction="3.8"/>
  </joint>
  <link name="left_arm_link_4">
    <inertial>
      <mass value="0.9"/>
      <origin xyz="0 -0.061 0.204"/>
      <inertia ixx="6.79e-3" ixy="0" ixz="0" iyy="4.91e-3" iyz="2.67e-3" izz="3.40e-3"/>
    </inertial>
    <visual>
      <origin rpy="0 0 0" xyz="0 0 0"/>
      <geometry>
        <mesh filename="package://prbt_support/meshes/link_4.dae"/>
      </geometry>
    </visual>
    <collision>
      <origin rpy="0.966643893412 0 0" xyz="0 -0.04 0.162"/>
      <geometry>
        <box size="0.121 0.08 0.17"/>
      </geometry>
    </collision>
    <collision>
      <origin rpy="-0.10471975512 0 0" xyz="0 -0.115 0.25"/>
      <geometry>
        <box size="0.09 0.06 0.12"/>
      </geometry>
    </collision>
  </link>
  <!-- joint between arm_4_link and arm_5_link -->
  <joint name="left_arm_joint_5" type="revolute">
    <origin rpy="1.57079632679 0 3.14159265359" xyz="0 0 0.307"/>
    <parent link="left_arm_link_4"/>
    <child link="left_arm_link_5"/>
    <axis xyz="0 0 1"/>
    <limit effort="41.6" lower="-2.96706" upper="2.96706" velocity="1.57"/>
    <dynamics damping="1.5" friction="3.5"/>
  </joint>
  <link name="left_arm_link_5">
    <inertial>
      <mass value="2.6"/>
      <origin xyz="-0.001 0.021 -0.032"/>
      <inertia ixx="7.37e-3" ixy="4.78e-6" ixz="6.00e-5" iyy="5.87e-3" iyz="-1.71e-3" izz="3.96e-3"/>
    </inertial>
    <visual>
      <origin rpy="0 0 0" xyz="0 0 0"/>
      <geometry>
        <mesh filename="package://prbt_support/meshes/link_5.dae"/>
      </geometry>
    </visual>
    <collision>
      <origin rpy="0 0 0" xyz="0 0 -0.095"/>
      <geometry>
        <cylinder length="0.08" radius="0.045"/>
      </geometry>
    </collision>
    <collision>
      <origin rpy="0 0 0" xyz="0 0 -0.06"/>
      <geometry>
        <cylinder length="0.04" radius="0.0545"/>
      </geometry>
    </collision>
    <collision>
      <origin rpy="0 0 0" xyz="0 0 0"/>
      <geometry>
        <sphere radius="0.07"/>
      </geometry>
    </collision>
    <collision>
      <origin rpy="0 1.57079632679 1.57079632679" xyz="0 0.05 0"/>
      <geometry>
        <cylinder length="0.03" radius="0.05"/>
      </geometry>
    </collision>
    <collision>
      <origin rpy="0 1.57079632679 1.57079632679" xyz="0 0.05 0"/>
      <geometry>
        <cylinder length="0.049" radius="0.0435"/>
      </geometry>
    </collision>
  </link>
  <!-- joint between arm_5_link and flange -->
  <joint name="left_arm_joint_6" type="revolute">
    <origin rpy="-1.57079632679 0 0" xyz="0 0.084 0"/>
    <parent link="left_arm_link_5"/>
    <child link="left_arm_flange"/>
    <axis xyz="0 0 1"/>
    <limit effort="20.1" lower="-3.12414" upper="3.12414" velocity="1.57"/>
    <dynamics damping="4.5" friction="7.0"/>
  </joint>
  <!-- Flange -->
  <link name="left_arm_flange">
    <inertial>
      <mass value="0.02"/>
      <origin xyz="0 0 0"/>
      <inertia ixx="0" ixy="0" ixz="0" iyy="0" iyz="0" izz="0"/>
    </inertial>
    <visual>
      <origin rpy="0 0 0" xyz="0 0 0"/>
      <geometry>
        <mesh filename="package://prbt_support/meshes/flange.dae"/>
      </geometry>
    </visual>
    <collision>
      <origin rpy="0 0 0" xyz="0 0 -0.0035"/>
      <geometry>
        <cylinder length="0.02" radius="0.0331"/>
      </geometry>
    </collision>
  </link>
  <!-- ROS-Industrial 'base' frame: base_link to robot world coordinate sytem transform -->
  <link name="left_arm_base"/>
  <joint name="left_arm_base_link-base" type="fixed">
    <origin rpy="0 0 0" xyz="0 0 0"/>
    <parent link="left_arm_base_link"/>
    <child link="left_arm_base"/>
  </joint>
  <!-- ROS-Industrial 'tool0' frame: all-zeros tool frame -->
  <link name="left_arm_tool0"/>
  <joint name="left_arm_flange-tool0" type="fixed">
    <origin rpy="0 0 0" xyz="0 0 0"/>
    <parent link="left_arm_flange"/>
    <child link="left_arm_tool0"/>
  </joint>
  <!-- transmissions for gazebo -->
  <transmission name="left_arm_joint_1_trans">
    <type>transmission_interface/SimpleTransmission</type>
    <joint name="left_arm_joint_1">
      <hardwareInterface>hardware_interface/PositionJointInterface</hardwareInterface>
    </joint>
    <actuator name="left_arm_joint_1_motor"/>
  </transmission>
  <transmission name="left_arm_joint_2_trans">
    <type>transmission_interface/SimpleTransmission</type>
    <joint name="left_arm_joint_2">
      <hardwareInterface>hardware_interface/PositionJointInterface</hardwareInterface>
    </joint>
    <actuator name="left_arm_joint_2_motor"/>
  </transmission>
  <transmission name="left_arm_joint_3_trans">
    <type>transmission_interface/SimpleTransmission</type>
    <joint name="left_arm_joint_3">
      <hardwareInterface>hardware_interface/PositionJointInterface</hardwareInterface>
    </joint>
    <actuator name="left_arm_joint_3_motor"/>
  </transmission>
  <transmission name="left_arm_joint_4_trans">
    <type>transmission_interface/SimpleTransmission</type>
    <joint name="left_arm_joint_4">
      <hardwareInterface>hardware_interface/PositionJointInterface</hardwareInterface>
    </joint>
    <actuator name="left_arm_joint_4_motor"/>
  </transmission>
  <transmission name="left_arm_joint_5_trans">
    <type>transmission_interface/SimpleTransmission</type>
    <joint name="left_arm_joint_5">
      <hardwareInterface>hardware_interface/PositionJointInterface</hardwareInterface>
    </joint>
    <actuator name="left_arm_joint_5_motor"/>
  </transmission>
  <transmission name="left_arm_joint_6_trans">
    <type>transmission_interface/SimpleTransmission</type>
    <joint name="left_arm_joint_6">
      <hardwareInterface>hardware_interface/PositionJointInterface</hardwareInterface>
    </joint>
    <actuator name="left_arm_joint_6_motor"/>
  </transmission>
  <gazebo>
    <plugin filename="libgazebo_ros_control.so" name="gazebo_ros_control">
      <robotNamespace>left_arm</robotNamespace>
      <robotSimType>gazebo_ros_control/DefaultRobotHWSim</robotSimType>
      <legacyModeNS>false</legacyModeNS>
      <!-- Only used from ros-kinetic-gazebo-ros-control 2.5.18 -->
    </plugin>
  </gazebo>
  <gazebo reference="left_arm_joint_1">
    <provideFeedback>true</provideFeedback>
  </gazebo>
  <gazebo>
    <plugin filename="libgazebo_ros_ft_sensor.so" name="ft_sensor">
      <updateRate>100.0</updateRate>
      <topicName>left_arm/ft_sensor/joint_1</topicName>
      <jointName>left_arm_joint_1</jointName>
    </plugin>
  </gazebo>
  <gazebo reference="left_arm_joint_2">
    <provideFeedback>true</provideFeedback>
  </gazebo>
  <gazebo>
    <plugin filename="libgazebo_ros_ft_sensor.so" name="ft_sensor">
      <updateRate>100.0</updateRate>
      <topicName>left_arm/ft_sensor/joint_2</topicName>
      <jointName>left_arm_joint_2</jointName>
    </plugin>
  </gazebo>
  <gazebo reference="left_arm_joint_3">
    <provideFeedback>true</provideFeedback>
  </gazebo>
  <gazebo>
    <plugin filename="libgazebo_ros_ft_sensor.so" name="ft_sensor">
      <updateRate>100.0</updateRate>
      <topicName>left_arm/ft_sensor/joint_3</topicName>
      <jointName>left_arm_joint_3</jointName>
    </plugin>
  </gazebo>
  <gazebo reference="left_arm_joint_4">
    <provideFeedback>true</provideFeedback>
  </gazebo>
  <gazebo>
    <plugin filename="libgazebo_ros_ft_sensor.so" name="ft_sensor">
      <updateRate>100.0</updateRate>
      <topicName>left_arm/ft_sensor/joint_4</topicName>
      <jointName>left_arm_joint_4</jointName>
    </plugin>
  </gazebo>
  <gazebo reference="left_arm_joint_5">
    <provideFeedback>true</provideFeedback>
  </gazebo>
  <gazebo>
    <plugin filename="libgazebo_ros_ft_sensor.so" name="ft_sensor">
      <updateRate>100.0</updateRate>
      <topicName>left_arm/ft_sensor/joint_5</topicName>
      <jointName>left_arm_joint_5</jointName>
    </plugin>
  </gazebo>
  <gazebo reference="left_arm_joint_6">
    <provideFeedback>true</provideFeedback>
  </gazebo>
  <gazebo>
    <plugin filename="libgazebo_ros_ft_sensor.so" name="ft_sensor">
      <updateRate>100.0</updateRate>
      <topicName>left_arm/ft_sensor/joint_6</topicName>
      <jointName>left_arm_joint_6</jointName>
    </plugin>
  </gazebo>
  <joint name="left_fixture_base_joint" type="fixed">
    <origin rpy="0 0 -0.523" xyz="0 0 0"/>
    <parent link="left_fixture"/>
    <child link="left_arm_base_link"/>
  </joint>
  <!-- robot foot link -->
  <link name="right_arm_base_link">
    <inertial>
      <mass value="2.4"/>
      <inertia ixx="0" ixy="0" ixz="0" iyy="0" iyz="0" izz="0"/>
    </inertial>
    <visual>
      <origin rpy="0 0 0" xyz="0 0 0"/>
      <geometry>
        <mesh filename="package://prbt_support/meshes/foot.dae"/>
      </geometry>
    </visual>
    <collision>
      <origin rpy="3.14159265359 0 0" xyz="0 0 0.065"/>
      <geometry>
        <cylinder length="0.13" radius="0.09275"/>
      </geometry>
    </collision>
  </link>
  <!-- arm 1 joint -->
  <joint name="right_arm_joint_1" type="revolute">
    <origin rpy="0 0 -3.14159265359" xyz="0 0 0.2604"/>
    <parent link="right_arm_base_link"/>
    <child link="right_arm_link_1"/>
    <axis xyz="0 0 1"/>
    <limit effort="370" lower="-2.96706" upper="2.96706" velocity="1.57"/>
    <dynamics damping="15.0" friction="11"/>
  </joint>
  <!-- arm 1 link -->
  <link name="right_arm_link_1">
    <inertial>
      <mass value="7.1"/>
      <origin xyz="0 -0.026 -0.051"/>
      <inertia ixx="3.53e-2" ixy="0" ixz="0" iyy="3.01e-2" iyz="9.04e-3" izz="1.87e-2"/>
    </inertial>
    <visual>
      <origin rpy="0 0 0" xyz="0 0 0"/>
      <geometry>
        <mesh filename="package://prbt_support/meshes/link_1.dae"/>
      </geometry>
    </visual>
    <collision>
      <origin rpy="0 0 0" xyz="0 0 -0.08"/>
      <geometry>
        <cylinder length="0.10" radius="0.07"/>
      </geometry>
    </collision>
    <collision>
      <origin rpy="0 0 0" xyz="0 0 0"/>
      <geometry>
        <sphere radius="0.09"/>
      </geometry>
    </collision>
    <collision>
      <origin rpy="0 1.57079632679 1.57079632679" xyz="0 -0.10 0"/>
      <geometry>
        <cylinder length="0.10" radius="0.065"/>
      </geometry>
    </collision>
  </link>
  <!-- joint between arm_1_link and arm_2_link -->
  <joint name="right_arm_joint_2" type="revolute">
    <origin rpy="1.57079632679 0 0" xyz="0 0 0"/>
    <parent link="right_arm_link_1"/>
    <child link="right_arm_link_2"/>
    <axis xyz="0 0 1"/>
    <limit effort="370" lower="-2.53073" upper="2.53073" velocity="1.57"/>
    <dynamics damping="12.0" friction="10.0"/>
  </joint>
  <link name="right_arm_link_2">
    <inertial>
      <mass value="1.7"/>
      <origin xyz="0 0.162 0.134"/>
      <inertia ixx="3.58e-2" ixy="0" ixz="0" iyy="3.22e-3" iyz="-1.45e-3" izz="3.66e-2"/>
    </inertial>
    <visual name="first">
      <origin rpy="0 0 0" xyz="0 0 0"/>
      <geometry>
        <mesh filename="package://prbt_support/meshes/link_2.dae"/>
      </geometry>
    </visual>
    <collision>
      <origin rpy="0.174532925199 0 0" xyz="0 0.15 0.145"/>
      <geometry>
        <box size="0.121 0.27 0.065"/>
      </geometry>
    </collision>
    <collision>
      <origin rpy="-0.448798950513 0 0" xyz="0 0.3 0.145"/>
      <geometry>
        <box size="0.11 0.1 0.075"/>
      </geometry>
    </collision>
  </link>
  <!-- joint between arm_2_link and arm_3_link -->
  <joint name="right_arm_joint_3" type="revolute">
    <origin rpy="0 3.14159265359 0" xyz="0 0.35 0"/>
    <parent link="right_arm_link_2"/>
    <child link="right_arm_link_3"/>
    <axis xyz="0 0 1"/>
    <limit effort="176" lower="-2.35620" upper="2.35620" velocity="1.57"/>
    <dynamics damping="4.5" friction="4.5"/>
  </joint>
  <link name="right_arm_link_3">
    <inertial>
      <mass value="4.8"/>
      <origin xyz="0 0.043 -0.027"/>
      <inertia ixx="2.06e-2" ixy="0" ixz="0" iyy="1.08e-2" iyz="-5.36e-3" izz="1.63e-2"/>
    </inertial>
    <visual>
      <origin rpy="0 0 0" xyz="0 0 0"/>
      <geometry>
        <mesh filename="package://prbt_support/meshes/link_3.dae"/>
      </geometry>
    </visual>
    <collision>
      <origin rpy="0 0 0" xyz="0 0 -0.11"/>
      <geometry>
        <cylinder length="0.10" radius="0.06"/>
      </geometry>
    </collision>
    <collision>
      <origin rpy="0 0 0" xyz="0 0 0"/>
      <geometry>
        <sphere radius="0.085"/>
      </geometry>
    </collision>
    <collision>
      <origin rpy="0 1.57079632679 1.57079632679" xyz="0 0.10 0"/>
      <geometry>
        <cylinder length="0.10" radius="0.065"/>
      </geometry>
    </collision>
  </link>
  <!-- joint between arm_3_link and arm_4_link -->
  <joint name="right_arm_joint_4" type="revolute">
    <origin rpy="-1.57079632679 3.14159265359 0" xyz="0 0 0"/>
    <parent link="right_arm_link_3"/>
    <child link="right_arm_link_4"/>
    <axis xyz="0 0 1"/>
    <limit effort="176" lower="-2.96706" upper="2.96706" velocity="1.57"/>
    <dynamics damping="4.2" friction="3.8"/>
  </joint>
  <link name="right_arm_link_4">
    <inertial>
      <mass value="0.9"/>
      <origin xyz="0 -0.061 0.204"/>
      <inertia ixx="6.79e-3" ixy="0" ixz="0" iyy="4.91e-3" iyz="2.67e-3" izz="3.40e-3"/>
    </inertial>
    <visual>
      <origin rpy="0 0 0" xyz="0 0 0"/>
      <geometry>
        <mesh filename="package://prbt_support/meshes/link_4.dae"/>
      </geometry>
    </visual>
    <collision>
      <origin rpy="0.966643893412 0 0" xyz="0 -0.04 0.162"/>
      <geometry>
        <box size="0.121 0.08 0.17"/>
      </geometry>
    </collision>
    <collision>
      <origin rpy="-0.10471975512 0 0" xyz="0 -0.115 0.25"/>
      <geometry>
        <box size="0.09 0.06 0.12"/>
      </geometry>
    </collision>
  </link>
  <!-- joint between arm_4_link and arm_5_link -->
  <joint name="right_arm_joint_5" type="revolute">
    <origin rpy="1.57079632679 0 3.14159265359" xyz="0 0 0.307"/>
    <parent link="right_arm_link_4"/>
    <child link="right_arm_link_5"/>
    <axis xyz="0 0 1"/>
    <limit effort="41.6" lower="-2.96706" upper="2.96706" velocity="1.57"/>
    <dynamics damping="1.5" friction="3.5"/>
  </joint>
  <link name="right_arm_link_5">
    <inertial>
      <mass value="2.6"/>
      <origin xyz="-0.001 0.021 -0.032"/>
      <inertia ixx="7.37e-3" ixy="4.78e-6" ixz="6.00e-5" iyy="5.87e-3" iyz="-1.71e-3" izz="3.96e-3"/>
    </inertial>
    <visual>
      <origin rpy="0 0 0" xyz="0 0 0"/>
      <geometry>
        <mesh filename="package://prbt_support/meshes/link_5.dae"/>
      </geometry>
    </visual>
    <collision>
      <origin rpy="0 0 0" xyz="0 0 -0.095"/>
      <geometry>
        <cylinder length="0.08" radius="0.045"/>
      </geometry>
    </collision>
    <collision>
      <origin rpy="0 0 0" xyz="0 0 -0.06"/>
      <geometry>
        <cylinder length="0.04" radius="0.0545"/>
      </geometry>
    </collision>
    <collision>
      <origin rpy="0 0 0" xyz="0 0 0"/>
      <geometry>
        <sphere radius="0.07"/>
      </geometry>
    </collision>
    <collision>
      <origin rpy="0 1.57079632679 1.57079632679" xyz="0 0.05 0"/>
      <geometry>
        <cylinder length="0.03" radius="0.05"/>
      </geometry>
    </collision>
    <collision>
      <origin rpy="0 1.57079632679 1.57079632679" xyz="0 0.05 0"/>
      <geometry>
        <cylinder length="0.049" radius="0.0435"/>
      </geometry>
    </collision>
  </link>
  <!-- joint between arm_5_link and flange -->
  <joint name="right_arm_joint_6" type="revolute">
    <origin rpy="-1.57079632679 0 0" xyz="0 0.084 0"/>
    <parent link="right_arm_link_5"/>
    <child link="right_arm_flange"/>
    <axis xyz="0 0 1"/>
    <limit effort="20.1" lower="-3.12414" upper="3.12414" velocity="1.57"/>
    <dynamics damping="4.5" friction="7.0"/>
  </joint>
  <!-- Flange -->
  <link name="right_arm_flange">
    <inertial>
      <mass value="0.02"/>
      <origin xyz="0 0 0"/>
      <inertia ixx="0" ixy="0" ixz="0" iyy="0" iyz="0" izz="0"/>
    </inertial>
    <visual>
      <origin rpy="0 0 0" xyz="0 0 0"/>
      <geometry>
        <mesh filename="package://prbt_support/meshes/flange.dae"/>
      </geometry>
    </visual>
    <collision>
      <origin rpy="0 0 0" xyz="0 0 -0.0035"/>
      <geometry>
        <cylinder length="0.02" radius="0.0331"/>
      </geometry>
    </collision>
  </link>
  <!-- ROS-Industrial 'base' frame: base_link to robot world coordinate sytem transform -->
  <link name="right_arm_base"/>
  <joint name="right_arm_base_link-base" type="fixed">
    <origin rpy="0 0 0" xyz="0 0 0"/>
    <parent link="right_arm_base_link"/>
    <child link="right_arm_base"/>
  </joint>
  <!-- ROS-Industrial 'tool0' frame: all-zeros tool frame -->
  <link name="right_arm_tool0"/>
  <joint name="right_arm_flange-tool0" type="fixed">
    <origin rpy="0 0 0" xyz="0 0 0"/>
    <parent link="right_arm_flange"/>
    <child link="right_arm_tool0"/>
  </joint>
  <!-- transmissions for gazebo -->
  <transmission name="right_arm_joint_1_trans">
    <type>transmission_interface/SimpleTransmission</type>
    <joint name="right_arm_joint_1">
      <hardwareInterface>hardware_interface/PositionJointInterface</hardwareInterface>
    </joint>
    <actuator name="right_arm_joint_1_motor"/>
  </transmission>
  <transmission name="right_arm_joint_2_trans">
    <type>transmission_interface/SimpleTransmission</type>
    <joint name="right_arm_joint_2">
      <hardwareInterface>hardware_interface/PositionJointInterface</hardwareInterface>
    </joint>
    <actuator name="right_arm_joint_2_motor"/>
  </transmission>
  <transmission name="right_arm_joint_3_trans">
    <type>transmission_interface/SimpleTransmission</type>
    <joint name="right_arm_joint_3">
      <hardwareInterface>hardware_interface/PositionJointInterface</hardwareInterface>
    </joint>
    <actuator name="right_arm_joint_3_motor"/>
  </transmission>
  <transmission name="right_arm_joint_4_trans">
    <type>transmission_interface/SimpleTransmission</type>
    <joint name="right_arm_joint_4">
      <hardwareInterface>hardware_interface/PositionJointInterface</hardwareInterface>
    </joint>
    <actuator name="right_arm_joint_4_motor"/>
  </transmission>
  <transmission name="right_arm_joint_5_trans">
    <type>transmission_interface/SimpleTransmission</type>
    <joint name="right_arm_joint_5">
      <hardwareInterface>hardware_interface/PositionJointInterface</hardwareInterface>
    </joint>
    <actuator name="right_arm_joint_5_motor"/>
  </transmission>
  <transmission name="right_arm_joint_6_trans">
    <type>transmission_interface/SimpleTransmission</type>
    <joint name="right_arm_joint_6">
      <hardwareInterface>hardware_interface/PositionJointInterface</hardwareInterface>
    </joint>
    <actuator name="right_arm_joint_6_motor"/>
  </transmission>
  <gazebo>
    <plugin filename="libgazebo_ros_control.so" name="gazebo_ros_control">
      <robotNamespace>right_arm</robotNamespace>
      <robotSimType>gazebo_ros_control/DefaultRobotHWSim</robotSimType>
      <legacyModeNS>false</legacyModeNS>
      <!-- Only used from ros-kinetic-gazebo-ros-control 2.5.18 -->
    </plugin>
  </gazebo>
  <gazebo reference="right_arm_joint_1">
    <provideFeedback>true</provideFeedback>
  </gazebo>
  <gazebo>
    <plugin filename="libgazebo_ros_ft_sensor.so" name="ft_sensor">
      <updateRate>100.0</updateRate>
      <topicName>right_arm/ft_sensor/joint_1</topicName>
      <jointName>right_arm_joint_1</jointName>
    </plugin>
  </gazebo>
  <gazebo reference="right_arm_joint_2">
    <provideFeedback>true</provideFeedback>
  </gazebo>
  <gazebo>
    <plugin filename="libgazebo_ros_ft_sensor.so" name="ft_sensor">
      <updateRate>100.0</updateRate>
      <topicName>right_arm/ft_sensor/joint_2</topicName>
      <jointName>right_arm_joint_2</jointName>
    </plugin>
  </gazebo>
  <gazebo reference="right_arm_joint_3">
    <provideFeedback>true</provideFeedback>
  </gazebo>
  <gazebo>
    <plugin filename="libgazebo_ros_ft_sensor.so" name="ft_sensor">
      <updateRate>100.0</updateRate>
      <topicName>right_arm/ft_sensor/joint_3</topicName>
      <jointName>right_arm_joint_3</jointName>
    </plugin>
  </gazebo>
  <gazebo reference="right_arm_joint_4">
    <provideFeedback>true</provideFeedback>
  </gazebo>
  <gazebo>
    <plugin filename="libgazebo_ros_ft_sensor.so" name="ft_sensor">
      <updateRate>100.0</updateRate>
      <topicName>right_arm/ft_sensor/joint_4</topicName>
      <jointName>right_arm_joint_4</jointName>
    </plugin>
  </gazebo>
  <gazebo reference="right_arm_joint_5">
    <provideFeedback>true</provideFeedback>
  </gazebo>
  <gazebo>
    <plugin filename="libgazebo_ros_ft_sensor.so" name="ft_sensor">
      <updateRate>100.0</updateRate>
      <topicName>right_arm/ft_sensor/joint_5</topicName>
      <jointName>right_arm_joint_5</jointName>
    </plugin>
  </gazebo>
  <gazebo reference="right_arm_joint_6">
    <provideFeedback>true</provideFeedback>
  </gazebo>
  <gazebo>
    <plugin filename="libgazebo_ros_ft_sensor.so" name="ft_sensor">
      <updateRate>100.0</updateRate>
      <topicName>right_arm/ft_sensor/joint_6</topicName>
      <jointName>right_arm_joint_6</jointName>
    </plugin>
  </gazebo>
  <joint name="right_fixture_base_joint" type="fixed">
    <origin rpy="0 0 0.523" xyz="0 0 0"/>
    <parent link="right_fixture"/>
    <child link="right_arm_base_link"/>
  </joint>
  <!--real gripper for left arm PG plus 70-->
  <!-- <xacro:prbt_gripper gripper_name="left_gripper" parent="left_arm_flange" /> -->
  <!-- real gripper for right arm PG plus 70 -->
  <!-- <xacro:prbt_gripper gripper_name="right_gripper" parent="right_arm_flange" /> -->
  <!-- Add gripper brackets -->
  <!-- <xacro:simple_gripper_brackets
      gripper_name="right_gripper"
      parent_left="right_gripper_finger_left_link"
      parent_right="right_gripper_finger_right_link"/> -->
  <!-- Add gripper brackets -->
  <!-- <xacro:simple_gripper_brackets
      gripper_name="left_gripper"
      parent_left="left_gripper_finger_left_link"
      parent_right="left_gripper_finger_right_link"/> -->
</robot>

